#VRML_SIM R2022a utf8
WorldInfo {
}
Viewpoint {
  orientation -0.5773502691896258 0.5773502691896258 0.5773502691896258 2.0944
  position 0.5165994701966019 0.20251789031196288 6.326593053308034
}
TexturedBackground {
}
TexturedBackgroundLight {
}
RectangleArena {
  floorSize 5 5
  wallHeight 0.3
}
Robot {
  translation 0.3575852318544556 0.06834869779742585 0.06767256625262254
  rotation 2.2044580712926362e-05 8.60149294810428e-06 -0.9999999997200255 1.4846099957935552
  children [
    DEF Body Shape {
      appearance PBRAppearance {
        metalness 0
      }
      geometry Box {
        size 0.3 0.3 0.1
      }
    }
    HingeJoint {
      jointParameters HingeJointParameters {
        position 524.3922298154265
        axis 0 1 0
        anchor 0.12004 0.17 0.000111208
      }
      device [
        RotationalMotor {
          name "wheel1"
        }
      ]
      endPoint Solid {
        translation 0.12004011150750288 0.16999998943115 0.00011123677398876914
        rotation -0.4798265305198215 -0.6206342457225126 -0.6201448489230229 2.24620875083613
        children [
          DEF Wheel Shape {
            appearance PBRAppearance {
            }
            geometry Cylinder {
              height 0.03
              radius 0.07
            }
          }
        ]
        boundingObject USE Wheel
        physics DEF Physics_wheel Physics {
        }
        linearVelocity 4.747399408732813e-11 -6.890150655454864e-11 2.2299874256663949e-07
        angularVelocity 2.7420415860867823e-09 2.4559832025302496e-10 1.1426193604886201e-09
      }
    }
    HingeJoint {
      jointParameters HingeJointParameters {
        position 386.25288128721365
        axis 0 1 0
        anchor -0.12 0.17 0.000142255
      }
      device [
        RotationalMotor {
          name "wheel2"
        }
      ]
      endPoint Solid {
        translation -0.12000576036575342 0.16999996603374848 0.0001770467441448109
        rotation 0.05763905788853587 -0.7062115713396651 -0.7056507319571655 3.2568346763961222
        children [
          USE Wheel
        ]
        name "solid(1)"
        boundingObject USE Wheel
        physics USE Physics_wheel
        linearVelocity -8.475049961107743e-11 5.562402557528494e-10 2.1421079973357301e-07
        angularVelocity -1.0491666527256051e-08 -9.173869588370266e-10 1.142410404461345e-09
      }
    }
    HingeJoint {
      jointParameters HingeJointParameters {
        position 347.24890637025396
        axis 0 1 0
        anchor 0.12 -0.17 0.000150625
      }
      device [
        RotationalMotor {
          name "wheel3"
        }
      ]
      endPoint Solid {
        translation 0.12000001124316978 -0.16999997711353795 0.00015073343184390738
        rotation -0.5376124090568061 -0.5964629615429432 0.5959906317515056 4.128819355686188
        children [
          USE Wheel
        ]
        name "solid(2)"
        boundingObject USE Wheel
        physics USE Physics_wheel
        linearVelocity 3.5380878470304666e-11 -6.932059501803039e-12 2.187890282343841e-07
        angularVelocity -1.2601200389057209e-09 -9.723999923059184e-11 1.142560766965039e-09
      }
    }
    HingeJoint {
      jointParameters HingeJointParameters {
        position 170.16587852789038
        axis 0 1 0
        anchor -0.12 -0.17 0.000146469
      }
      device [
        RotationalMotor {
          name "wheel4"
        }
      ]
      endPoint Solid {
        translation -0.11999996265374446 -0.16999993783649273 0.00014644797067678056
        rotation -0.9359360020930441 -0.2491207737946957 0.24892296007002157 4.64702176649055
        children [
          USE Wheel
        ]
        name "solid(3)"
        boundingObject USE Wheel
        physics USE Physics_wheel
        linearVelocity 9.939663474947697e-12 -5.73703031900154e-10 2.1850737647487041e-07
        angularVelocity 1.0344642471829341e-08 8.841596443330266e-10 1.142737430598222e-09
      }
    }
    DistanceSensor {
      translation 0.13 0.06 0
      rotation 0 0 1 0.3
      children [
        DEF Sensor Shape {
          appearance PBRAppearance {
            baseColor 1 0 0
            metalness 0
          }
          geometry Box {
            size 0.05 0.035 0.025
          }
        }
      ]
      name "ds_left"
      boundingObject USE Sensor
      physics Physics {
      }
      lookupTable [
        0 0 0
        0.5 1000 0
      ]
      aperture 1.5709
    }
    DistanceSensor {
      translation 0.13 -0.06 0
      rotation 0 0 1 -0.3
      children [
        DEF Sensor Shape {
          appearance PBRAppearance {
            baseColor 1 0 0
            metalness 0
          }
          geometry Box {
            size 0.05 0.035 0.025
          }
        }
      ]
      name "ds_right"
      boundingObject USE Sensor
      physics Physics {
      }
      lookupTable [
        0 0 0
        0.5 1000 0
      ]
    }
    GPS {
      translation 0 0 0.06
      children [
        Solid {
          children [
            Shape {
              appearance PBRAppearance {
                baseColor 0 0.3 0.6
                metalness 0
              }
              geometry Cylinder {
                height 0.02
                radius 0.01
              }
            }
          ]
        }
      ]
      name "global"
    }
    InertialUnit {
      translation 0.09 3.18432e-07 0.12
      rotation 1 0 0 -5.307179586466759e-06
      children [
        Shape {
          appearance PBRAppearance {
            baseColor 1 0.9 0
            metalness 0
          }
          geometry Box {
            size 0.03 0.03 0.03
          }
        }
      ]
      name "imu"
    }
    Solid {
      translation 0 0 0.15
      children [
        Shape {
          appearance PBRAppearance {
          }
          geometry Box {
            size 0.02 0.02 0.2
          }
        }
      ]
      name "solid(4)"
    }
    SliderJoint {
      jointParameters JointParameters {
      }
      device [
        LinearMotor {
          name "linear"
          maxPosition 0.15
        }
      ]
      endPoint Solid {
        translation 0 0.075 0.21
        children [
          Shape {
            appearance PBRAppearance {
              baseColor 1 0 0
              metalness 0
            }
            geometry Box {
              size 0.025 0.15 0.025
            }
          }
        ]
        name "solid(5)"
      }
    }
    Lidar {
      translation 0.09 0 0.08
      children [
        Shape {
          appearance PBRAppearance {
          }
          geometry Cylinder {
            height 0.05
            radius 0.05
          }
        }
      ]
      horizontalResolution 128
      fieldOfView 6.283
      numberOfLayers 1
    }
  ]
  boundingObject USE Body
  physics Physics {
  }
  controller "ros"
}
WoodenBox {
  translation -1.14 0 0.15
  rotation 0 1 0 0
  name "wooden box(1)"
  size 0.3 0.3 0.3
}
WoodenBox {
  translation 0.28 1.3 0.15
  rotation 0 1 0 0
  name "wooden box(2)"
  size 0.3 0.3 0.3
}
WoodenBox {
  translation -1.82 -1.21 0.15
  rotation 0 1 0 0
  name "wooden box(3)"
  size 0.3 0.3 0.3
}
Wall {
  translation 1.49 -1.53 0
  rotation 0 0 1 1.5708
  name "wall(2)"
  size 0.1 2 0.3
}
Wall {
  translation -1.48 1.33 -5.69638e-08
  rotation -9.58976e-09 -9.58979e-09 1 1.5708
  name "wall(3)"
  size 0.1 2 0.3
}
Wall {
  translation -0.44 -1.01 0
  name "wall(1)"
  size 0.1 3 0.3
}
Wall {
  translation 0.76 0.98 0
  size 0.1 3 0.3
}
WoodenBox {
  translation 0.15 -1.02 0.15
  rotation 0 1 0 0
  size 0.3 0.3 0.3
}
