#VRML_SIM R2022a utf8
WorldInfo {
}
Viewpoint {
  orientation -0.4615710342445473 0.8059580920514388 0.3706531184318077 0.6466982399451966
  position -3.1443700940367774 0.14194834811118326 1.19456285535571
}
TexturedBackground {
}
TexturedBackgroundLight {
}
RectangleArena {
  floorSize 5 5
  wallHeight 0.3
}
Robot {
  translation -0.5033497082034806 0.788693959495659 0.0676726678229893
  rotation 1.2111755384255954e-05 6.084872090623841e-05 0.9999999980753693 0.5192948851934973
  children [
    DEF Body Shape {
      appearance PBRAppearance {
        metalness 0
      }
      geometry Box {
        size 0.3 0.3 0.1
      }
    }
    HingeJoint {
      jointParameters HingeJointParameters {
        position 509.76799610082054
        axis 0 1 0
        anchor 0.12004 0.17 0.000111208
      }
      device [
        RotationalMotor {
          name "wheel1"
        }
      ]
      endPoint Solid {
        translation 0.12003992238265072 0.16999998943115 0.00011129307298467847
        rotation 0.26469722060668965 -0.682156859296962 -0.6816138208085267 3.659502878919069
        children [
          DEF Wheel Shape {
            appearance PBRAppearance {
            }
            geometry Cylinder {
              height 0.03
              radius 0.07
            }
          }
        ]
        boundingObject USE Wheel
        physics DEF Physics_wheel Physics {
        }
        linearVelocity -5.1455081773075426e-08 -4.648035704971117e-06 1.3076119543687551e-07
        angularVelocity 4.4651605937935514e-07 -1.3852978881265955e-06 1.0708867884846476e-08
      }
    }
    HingeJoint {
      jointParameters HingeJointParameters {
        position 292.49308001477226
        axis 0 1 0
        anchor -0.12 0.17 0.000142255
      }
      device [
        RotationalMotor {
          name "wheel2"
        }
      ]
      endPoint Solid {
        translation -0.11998877622906873 0.16999996603374848 0.00017568663532245175
        rotation 0.1151021351506979 0.7026860749570641 0.7021280357208259 3.3709688801150723
        children [
          USE Wheel
        ]
        name "solid(1)"
        boundingObject USE Wheel
        physics USE Physics_wheel
        linearVelocity 4.069175904214493e-06 -2.194616871830053e-06 -1.3084440110525676e-07
        angularVelocity 1.2272082432981552e-07 -8.066022857709472e-07 1.0981480829938118e-08
      }
    }
    HingeJoint {
      jointParameters HingeJointParameters {
        position 306.60917682019823
        axis 0 1 0
        anchor 0.12 -0.17 0.000150625
      }
      device [
        RotationalMotor {
          name "wheel3"
        }
      ]
      endPoint Solid {
        translation 0.1199999673374484 -0.16999997711353795 0.00015052099504164274
        rotation -0.6934394697949962 0.5096827357770933 -0.5092791087225281 4.354953362060887
        children [
          USE Wheel
        ]
        name "solid(2)"
        boundingObject USE Wheel
        physics USE Physics_wheel
        linearVelocity -3.861422569290866e-06 2.811707928521356e-06 1.3032318485331063e-07
        angularVelocity 9.437262122782213e-07 -1.0381234522599381e-06 -3.5533183371618414e-08
      }
    }
    HingeJoint {
      jointParameters HingeJointParameters {
        position 89.33425156166271
        axis 0 1 0
        anchor -0.12 -0.17 0.000146469
      }
      device [
        RotationalMotor {
          name "wheel4"
        }
      ]
      endPoint Solid {
        translation -0.11999999114187843 -0.16999993783649273 0.0001464270654209536
        rotation 0.654416621934066 0.5348799180228027 -0.5344551975912719 1.9819170202146366
        children [
          USE Wheel
        ]
        name "solid(3)"
        boundingObject USE Wheel
        physics USE Physics_wheel
        linearVelocity -4.2727819359663826e-07 3.879245520718489e-06 -1.305529549091938e-07
        angularVelocity 6.549360660564432e-07 -6.424900392554664e-07 -3.528813532477419e-08
      }
    }
    DistanceSensor {
      translation 0.13 0.06 0
      rotation 0 0 1 0.2
      children [
        DEF Sensor Shape {
          appearance PBRAppearance {
            baseColor 1 0 0
            metalness 0
          }
          geometry Box {
            size 0.05 0.035 0.025
          }
        }
      ]
      name "ds_left"
      boundingObject USE Sensor
      physics Physics {
      }
      lookupTable [
        0 0 0
        0.5 1000 0
      ]
      aperture 1.5709
    }
    DistanceSensor {
      translation 0.13 -0.06 0
      rotation 0 0 1 -0.2
      children [
        DEF Sensor Shape {
          appearance PBRAppearance {
            baseColor 1 0 0
            metalness 0
          }
          geometry Box {
            size 0.05 0.035 0.025
          }
        }
      ]
      name "ds_right"
      boundingObject USE Sensor
      physics Physics {
      }
      lookupTable [
        0 0 0
        0.5 1000 0
      ]
    }
    GPS {
      translation 0 0 0.06
      children [
        Solid {
          children [
            Shape {
              appearance PBRAppearance {
                baseColor 0 0.3 0.6
                metalness 0
              }
              geometry Cylinder {
                height 0.02
                radius 0.01
              }
            }
          ]
        }
      ]
      name "global"
    }
    InertialUnit {
      translation 0.09 3.18432e-07 0.12
      rotation 1 0 0 -5.307179586466759e-06
      children [
        Shape {
          appearance PBRAppearance {
            baseColor 1 0.9 0
            metalness 0
          }
          geometry Box {
            size 0.03 0.03 0.03
          }
        }
      ]
      name "imu"
    }
    Solid {
      translation 0 0 0.15
      children [
        Shape {
          appearance PBRAppearance {
          }
          geometry Box {
            size 0.02 0.02 0.2
          }
        }
      ]
      name "solid(4)"
    }
    SliderJoint {
      jointParameters JointParameters {
      }
      device [
        LinearMotor {
          name "linear"
          maxPosition 0.15
        }
      ]
      endPoint Solid {
        translation 0 0.075 0.21
        children [
          Shape {
            appearance PBRAppearance {
              baseColor 1 0 0
              metalness 0
            }
            geometry Box {
              size 0.025 0.15 0.025
            }
          }
          Camera {
            translation 0 0.07 0
            rotation 0 0 1 1.57
            name "CAM"
          }
        ]
        name "solid(5)"
      }
    }
    Lidar {
      translation 0.09 0 0.08
      children [
        Shape {
          appearance PBRAppearance {
          }
          geometry Cylinder {
            height 0.05
            radius 0.05
          }
        }
      ]
    }
  ]
  boundingObject USE Body
  physics Physics {
  }
  controller "keyboard"
  linearVelocity -7.128435536438632e-08 -3.9957684517231906e-08 1.4728312163634237e-09
  angularVelocity 5.514419953789921e-07 -9.622416512880358e-07 -7.522640946283446e-09
}
WoodenBox {
  translation -1.14 0 0.15
  rotation 0 1 0 0
  name "wooden box(1)"
  size 0.3 0.3 0.3
}
WoodenBox {
  translation 0.28 1.3 0.15
  rotation 0 1 0 0
  name "wooden box(2)"
  size 0.3 0.3 0.3
}
WoodenBox {
  translation -1.82 -1.21 0.15
  rotation 0 1 0 0
  name "wooden box(3)"
  size 0.3 0.3 0.3
}
Wall {
  translation 1.49 -1.53 0
  rotation 0 0 1 1.5708
  name "wall(2)"
  size 0.1 2 0.3
}
Wall {
  translation -1.48 1.33 -5.69638e-08
  rotation -9.58976e-09 -9.58979e-09 1 1.5708
  name "wall(3)"
  size 0.1 2 0.3
}
Wall {
  translation -0.44 -1.01 0
  name "wall(1)"
  size 0.1 3 0.3
}
Wall {
  translation 0.76 0.98 0
  size 0.1 3 0.3
}
WoodenBox {
  translation 0.15 -1.02 0.15
  rotation 0 1 0 0
  size 0.3 0.3 0.3
}
