#VRML_SIM R2022a utf8
WorldInfo {
}
Viewpoint {
  orientation 0.46364660313013 0.08715473405661565 -0.8817232444125607 3.281953488037194
  position 1.0688441370388568 0.3183985575885336 2.073916546376084
}
TexturedBackground {
}
TexturedBackgroundLight {
}
RectangleArena {
  floorSize 5 5
  wallHeight 0.3
}
Robot {
  translation -0.5033495153426294 0.7886939331473057 0.06767295176222077
  rotation 1.4201026512697265e-05 6.585627950210054e-05 0.9999999977306406 0.5192948852757879
  children [
    DEF Body Shape {
      appearance PBRAppearance {
        metalness 0
      }
      geometry Box {
        size 0.3 0.3 0.1
      }
    }
    HingeJoint {
      jointParameters HingeJointParameters {
        position 509.7679961016627
        axis 0 1 0
        anchor 0.12004 0.17 0.000111208
      }
      device [
        RotationalMotor {
          name "wheel1"
        }
      ]
      endPoint Solid {
        translation 0.1200399223826508 0.16999998943115 0.00011129307298474506
        rotation 0.26469722029954346 -0.6821568593565993 -0.6816138208681186 3.6595028783446004
        children [
          DEF Wheel Shape {
            appearance PBRAppearance {
            }
            geometry Cylinder {
              height 0.03
              radius 0.07
            }
          }
        ]
        boundingObject USE Wheel
        physics DEF Physics_wheel Physics {
        }
        linearVelocity 1.6101320075861062e-09 7.061127697912088e-11 2.2480538904874205e-07
        angularVelocity -1.3817184197520374e-09 2.3220908701150948e-08 -8.001833672525884e-10
      }
    }
    HingeJoint {
      jointParameters HingeJointParameters {
        position 292.493080015923
        axis 0 1 0
        anchor -0.12 0.17 0.000142255
      }
      device [
        RotationalMotor {
          name "wheel2"
        }
      ]
      endPoint Solid {
        translation -0.11998877622903026 0.16999996603374848 0.00017568663530953644
        rotation 0.11510213556004135 0.7026860749235119 0.7021280356873001 3.37096888092368
        children [
          USE Wheel
        ]
        name "solid(1)"
        boundingObject USE Wheel
        physics USE Physics_wheel
        linearVelocity 1.633635018764996e-09 1.3400905953098987e-10 2.1908462479188363e-07
        angularVelocity -1.673496463503264e-09 2.3714259762302488e-08 -8.001656272906581e-10
      }
    }
    HingeJoint {
      jointParameters HingeJointParameters {
        position 306.6091768205346
        axis 0 1 0
        anchor 0.12 -0.17 0.000150625
      }
      device [
        RotationalMotor {
          name "wheel3"
        }
      ]
      endPoint Solid {
        translation 0.11999996733744836 -0.16999997711353795 0.000150520995041652
        rotation -0.6934394699219125 0.509682735690688 -0.5092791086361911 4.354953362232345
        children [
          USE Wheel
        ]
        name "solid(2)"
        boundingObject USE Wheel
        physics USE Physics_wheel
        linearVelocity 1.3426568597405472e-09 -1.0828169679921902e-10 2.1718870893004403e-07
        angularVelocity 1.1187204175122484e-09 1.8837260144811448e-08 -8.002770810592834e-10
      }
    }
    HingeJoint {
      jointParameters HingeJointParameters {
        position 89.33425156188177
        axis 0 1 0
        anchor -0.12 -0.17 0.000146469
      }
      device [
        RotationalMotor {
          name "wheel4"
        }
      ]
      endPoint Solid {
        translation -0.11999999114187844 -0.16999993783649273 0.00014642706542095118
        rotation 0.6544166218504172 0.5348799180740147 -0.5344551976424433 1.981917020331808
        children [
          USE Wheel
        ]
        name "solid(3)"
        boundingObject USE Wheel
        physics USE Physics_wheel
        linearVelocity 1.2632720616639205e-09 -7.892607663899696e-11 2.1977930361507222e-07
        angularVelocity 1.6872093048382255e-09 1.7823383517467826e-08 -8.002993046089011e-10
      }
    }
    DistanceSensor {
      translation 0.13 0.06 0
      rotation 0 0 1 0.3
      children [
        DEF Sensor Shape {
          appearance PBRAppearance {
            baseColor 1 0 0
            metalness 0
          }
          geometry Box {
            size 0.05 0.035 0.025
          }
        }
      ]
      name "ds_left"
      boundingObject USE Sensor
      physics Physics {
      }
      lookupTable [
        0 0 0
        0.5 1000 0
      ]
      aperture 1.5709
    }
    DistanceSensor {
      translation 0.13 -0.06 0
      rotation 0 0 1 -0.3
      children [
        DEF Sensor Shape {
          appearance PBRAppearance {
            baseColor 1 0 0
            metalness 0
          }
          geometry Box {
            size 0.05 0.035 0.025
          }
        }
      ]
      name "ds_right"
      boundingObject USE Sensor
      physics Physics {
      }
      lookupTable [
        0 0 0
        0.5 1000 0
      ]
    }
    GPS {
      translation 0 0 0.06
      children [
        Solid {
          children [
            Shape {
              appearance PBRAppearance {
                baseColor 0 0.3 0.6
                metalness 0
              }
              geometry Cylinder {
                height 0.02
                radius 0.01
              }
            }
          ]
        }
      ]
      name "global"
    }
    InertialUnit {
      translation 0.09 3.18432e-07 0.12
      rotation 1 0 0 -5.307179586466759e-06
      children [
        Shape {
          appearance PBRAppearance {
            baseColor 1 0.9 0
            metalness 0
          }
          geometry Box {
            size 0.03 0.03 0.03
          }
        }
      ]
      name "imu"
    }
    Solid {
      translation 0 0 0.15
      children [
        Shape {
          appearance PBRAppearance {
          }
          geometry Box {
            size 0.02 0.02 0.2
          }
        }
      ]
      name "solid(4)"
    }
    SliderJoint {
      jointParameters JointParameters {
      }
      device [
        LinearMotor {
          name "linear"
          maxPosition 0.15
        }
      ]
      endPoint Solid {
        translation 0 0.075 0.21
        children [
          Shape {
            appearance PBRAppearance {
              baseColor 1 0 0
              metalness 0
            }
            geometry Box {
              size 0.025 0.15 0.025
            }
          }
          Camera {
            translation 0 0.07 0
            rotation 0 0 1 1.57
            name "CAM"
          }
        ]
        name "solid(5)"
      }
    }
    Lidar {
      translation 0.09 0 0.08
      children [
        Shape {
          appearance PBRAppearance {
          }
          geometry Cylinder {
            height 0.05
            radius 0.05
          }
        }
      ]
    }
  ]
  boundingObject USE Body
  physics Physics {
  }
  controller "keyboard"
}
WoodenBox {
  translation -1.14 0 0.15
  rotation 0 1 0 0
  name "wooden box(1)"
  size 0.3 0.3 0.3
}
WoodenBox {
  translation 0.28 1.3 0.15
  rotation 0 1 0 0
  name "wooden box(2)"
  size 0.3 0.3 0.3
}
WoodenBox {
  translation -1.82 -1.21 0.15
  rotation 0 1 0 0
  name "wooden box(3)"
  size 0.3 0.3 0.3
}
Wall {
  translation 1.49 -1.53 0
  rotation 0 0 1 1.5708
  name "wall(2)"
  size 0.1 2 0.3
}
Wall {
  translation -1.48 1.33 -5.69638e-08
  rotation -9.58976e-09 -9.58979e-09 1 1.5708
  name "wall(3)"
  size 0.1 2 0.3
}
Wall {
  translation -0.44 -1.01 0
  name "wall(1)"
  size 0.1 3 0.3
}
Wall {
  translation 0.76 0.98 0
  size 0.1 3 0.3
}
WoodenBox {
  translation 0.15 -1.02 0.15
  rotation 0 1 0 0
  size 0.3 0.3 0.3
}
