#VRML_SIM R2022a utf8
WorldInfo {
}
Viewpoint {
  orientation -0.6043086821291522 0.6289773596437519 0.4890792346429171 2.1998839744123173
  position 0.2241111976839758 4.639571760095856 21.49390611963847
  follow "robot"
  followType "None"
}
TexturedBackground {
}
TexturedBackgroundLight {
}
RectangleArena {
  floorSize 8 8
  wallHeight 0.3
}
Robot {
  translation -0.11631918535808994 -0.0041499477199881535 0.06755226388397824
  rotation -0.046115147868482316 0.07455219814626826 0.9961502712385455 0.029888964772974206
  children [
    DEF Body Shape {
      appearance PBRAppearance {
        metalness 0
      }
      geometry Box {
        size 0.3 0.3 0.1
      }
    }
    HingeJoint {
      jointParameters HingeJointParameters {
        position 524.3922298528461
        axis 0 1 0
        anchor 0.12004 0.17 0.000111208
      }
      device [
        RotationalMotor {
          name "wheel1"
        }
      ]
      endPoint Solid {
        translation 0.12004000002863292 0.17 0.000993010999999999
        rotation -0.47982650667724674 -0.6206342547996694 -0.6201448582864888 2.246208788912576
        children [
          DEF Wheel Shape {
            appearance PBRAppearance {
            }
            geometry Cylinder {
              height 0.03
              radius 0.07
            }
          }
        ]
        boundingObject USE Wheel
        physics DEF Physics_wheel Physics {
        }
        linearVelocity 1.4475093660200371e-08 8.769696074518407e-10 -2.552670955285627e-06
        angularVelocity -1.533529547989685e-08 2.046053284808674e-07 -5.820106283300025e-09
      }
    }
    HingeJoint {
      jointParameters HingeJointParameters {
        position 386.252881306275
        axis 0 1 0
        anchor -0.12 0.17 0
      }
      device [
        RotationalMotor {
          name "wheel2"
        }
      ]
      endPoint Solid {
        translation -0.12 0.170046 0
        rotation -3.1380139273158595e-06 0.7070942205343795 0.7071193416086363 3.141503453998336
        children [
          USE Wheel
        ]
        name "solid(1)"
        boundingObject USE Wheel
        physics USE Physics_wheel
        linearVelocity 1.4286809828005235e-08 1.2790403414169257e-09 -2.532534053594103e-06
        angularVelocity -1.5582246340329106e-08 2.1074924305604125e-07 -5.828474672713773e-09
      }
    }
    HingeJoint {
      jointParameters HingeJointParameters {
        position 347.2489063869444
        axis 0 1 0
        anchor 0.12 -0.17 0
      }
      device [
        RotationalMotor {
          name "wheel3"
        }
      ]
      endPoint Solid {
        translation 0.12000000000091941 -0.17 4.2919199999996856e-05
        rotation 0.5376121814731863 0.5964618237961433 -0.595991975688784 2.1543628448156866
        children [
          USE Wheel
        ]
        name "solid(2)"
        boundingObject USE Wheel
        physics USE Physics_wheel
        linearVelocity 1.2691131829037366e-08 8.002824379333795e-10 -2.572095976589699e-06
        angularVelocity -1.4921976672788203e-08 1.9086708163796633e-07 -5.801725103750301e-09
      }
    }
    HingeJoint {
      jointParameters HingeJointParameters {
        position 170.1658785167574
        axis 0 1 0
        anchor -0.12 -0.17 0
      }
      device [
        RotationalMotor {
          name "wheel4"
        }
      ]
      endPoint Solid {
        translation -0.12000000000036674 -0.17 3.187390000000569e-05
        rotation 0.9359358958457519 0.24912065916618928 -0.24892347427274336 1.6361611218883898
        children [
          USE Wheel
        ]
        name "solid(3)"
        boundingObject USE Wheel
        physics USE Physics_wheel
        linearVelocity 1.067440342850962e-08 1.1934071069817024e-09 -2.5072047084834593e-06
        angularVelocity -1.3435130308821776e-08 1.383738649638551e-07 -5.730870863778835e-09
      }
    }
    DistanceSensor {
      translation 0.13 0.06 0
      rotation 0 0 1 0.3
      children [
        DEF Sensor Shape {
          appearance PBRAppearance {
            baseColor 1 0 0
            metalness 0
          }
          geometry Box {
            size 0.05 0.035 0.025
          }
        }
      ]
      name "ds_left"
      boundingObject USE Sensor
      physics Physics {
      }
      lookupTable [
        0 0 0
        0.5 1000 0
      ]
      aperture 1.5709
    }
    DistanceSensor {
      translation 0.13 -0.06 0
      rotation 0 0 1 -0.3
      children [
        DEF Sensor Shape {
          appearance PBRAppearance {
            baseColor 1 0 0
            metalness 0
          }
          geometry Box {
            size 0.05 0.035 0.025
          }
        }
      ]
      name "ds_right"
      boundingObject USE Sensor
      physics Physics {
      }
      lookupTable [
        0 0 0
        0.5 1000 0
      ]
    }
    GPS {
      translation 0 0 0.06
      children [
        Solid {
          children [
            Shape {
              appearance PBRAppearance {
                baseColor 0 0.3 0.6
                metalness 0
              }
              geometry Cylinder {
                height 0.02
                radius 0.01
              }
            }
          ]
        }
      ]
      name "global"
    }
    InertialUnit {
      translation 0.09 3.18432e-07 0.12
      rotation 1 0 0 -5.307179586466759e-06
      children [
        Shape {
          appearance PBRAppearance {
            baseColor 1 0.9 0
            metalness 0
          }
          geometry Box {
            size 0.03 0.03 0.03
          }
        }
      ]
      name "imu"
    }
    Solid {
      translation 0 0 0.15
      children [
        Shape {
          appearance PBRAppearance {
          }
          geometry Box {
            size 0.02 0.02 0.2
          }
        }
      ]
      name "solid(4)"
    }
    SliderJoint {
      jointParameters JointParameters {
      }
      device [
        LinearMotor {
          name "linear"
          maxPosition 0.15
        }
      ]
      endPoint Solid {
        translation 0 0.075 0.21
        children [
          Shape {
            appearance PBRAppearance {
              baseColor 1 0 0
              metalness 0
            }
            geometry Box {
              size 0.025 0.15 0.025
            }
          }
        ]
        name "solid(5)"
      }
    }
    Lidar {
      translation 0.09 0 0.08
      children [
        Shape {
          appearance PBRAppearance {
          }
          geometry Cylinder {
            height 0.05
            radius 0.05
          }
        }
      ]
      horizontalResolution 256
      fieldOfView 6.2835
      numberOfLayers 1
      maxRange 6
    }
  ]
  boundingObject USE Body
  physics Physics {
  }
  controller "ros"
  linearVelocity 1.2968301274156068e-08 1.0254155706946738e-09 -2.539572001477644e-06
  angularVelocity -1.4513190472819042e-08 1.7646339484226617e-07 -5.785718257560537e-09
}
WoodenBox {
  translation -2 0 0.15
  rotation 0 1 0 0
  name "wooden box(1)"
  size 0.3 0.3 0.3
}
WoodenBox {
  translation -0.71 3.16 0.15
  rotation 0 1 0 0
  name "wooden box(2)"
  size 0.3 0.3 0.3
}
WoodenBox {
  translation -2.56 -2.23 0.15
  rotation 0 1 0 0
  name "wooden box(3)"
  size 0.3 0.3 0.3
}
Wall {
  translation 0.6 -0.97 0
  rotation 0 0 1 1.5708
  name "wall(2)"
  size 0.1 2 0.3
}
Wall {
  translation -2.94 1.23 -8.49666e-08
  rotation -9.58976e-09 -9.58979e-09 1 1.5708
  name "wall(3)"
  size 0.1 2 0.3
}
Wall {
  translation -1.88 1.68 -5.60048e-08
  rotation -9.58976e-09 -9.58979e-09 1 3.14159
  name "wall(4)"
  size 0.1 1 0.3
}
Wall {
  translation -0.44 -2.45 0
  name "wall(1)"
  size 0.1 3 0.3
}
Wall {
  translation 0.76 2.47 0
  size 0.1 3 0.3
}
WoodenBox {
  translation 2.39 1.77 0.15
  rotation 0 1 0 0
  size 0.3 0.3 0.3
}
WoodenBox {
  translation 2.18 -2.59 0.15
  rotation 0 1 0 0
  name "wooden box(4)"
  size 0.3 0.3 0.3
}
