#VRML_SIM R2022a utf8
WorldInfo {
}
Viewpoint {
  orientation -0.5792741729281214 0.5771059474750762 0.5756649702451377 2.1001695840115877
  position 2.5794985285865697e-05 -0.00781517505787301 20.740232379987013
  follow "robot"
  followType "None"
}
TexturedBackground {
}
TexturedBackgroundLight {
}
RectangleArena {
  floorSize 8 8
  wallHeight 0.3
}
Robot {
  translation -1.2095731422589175 -1.648175137151942 0.06772135811710184
  rotation -0.0007697530435129215 0.0005074539310677081 0.9999995749852896 1.1251770476873493
  children [
    DEF Body Shape {
      appearance PBRAppearance {
        metalness 0
      }
      geometry Box {
        size 0.3 0.3 0.1
      }
    }
    HingeJoint {
      jointParameters HingeJointParameters {
        position 491.593991757552
        axis 0 1 0
        anchor 0.12004 0.17 0.000111208
      }
      device [
        RotationalMotor {
          name "wheel1"
        }
      ]
      endPoint Solid {
        translation 0.11917381437769248 0.17 0.00027643208576459395
        rotation -0.023071295691678397 0.7071991825642703 0.7066378361618738 3.0954307743635856
        children [
          DEF Wheel Shape {
            appearance PBRAppearance {
            }
            geometry Cylinder {
              height 0.03
              radius 0.07
            }
          }
        ]
        boundingObject USE Wheel
        physics DEF Physics_wheel Physics {
        }
        linearVelocity -5.1682887717587977e-08 -7.92637282395225e-08 -2.5618235225456787e-06
        angularVelocity -3.396239345257987e-07 1.686246275245768e-07 -1.3723429536072969e-08
      }
    }
    HingeJoint {
      jointParameters HingeJointParameters {
        position 353.454644156354
        axis 0 1 0
        anchor -0.12 0.17 0
      }
      device [
        RotationalMotor {
          name "wheel2"
        }
      ]
      endPoint Solid {
        translation -0.12 0.170046 0
        rotation 0.5049474149973912 -0.6103136480697671 -0.6103649392512852 4.076816507033284
        children [
          USE Wheel
        ]
        name "solid(1)"
        boundingObject USE Wheel
        physics USE Physics_wheel
        linearVelocity -2.6826745162748928e-08 1.7685815755843667e-07 -2.5186171843489996e-06
        angularVelocity -2.0299684420721543e-07 1.0994759447590147e-07 -1.3651315704544447e-08
      }
    }
    HingeJoint {
      jointParameters HingeJointParameters {
        position 322.7674458187677
        axis 0 1 0
        anchor 0.12 -0.17 0
      }
      device [
        RotationalMotor {
          name "wheel3"
        }
      ]
      endPoint Solid {
        translation 0.12002601785249138 -0.17 3.41339871737306e-05
        rotation 0.29241927853775995 0.6764663322558304 -0.6759321466418061 2.572185606479296
        children [
          USE Wheel
        ]
        name "solid(2)"
        boundingObject USE Wheel
        physics USE Physics_wheel
        linearVelocity -4.0607376146218515e-08 -7.747286617584552e-08 -2.5712118720031255e-06
        angularVelocity -1.7053927399468887e-07 8.7161852495966e-08 -1.3625097452116682e-08
      }
    }
    HingeJoint {
      jointParameters HingeJointParameters {
        position 145.6841467318544
        axis 0 1 0
        anchor -0.12 -0.17 0
      }
      device [
        RotationalMotor {
          name "wheel4"
        }
      ]
      endPoint Solid {
        translation -0.1199806847452206 -0.17 2.5354810865342327e-05
        rotation 0.7293644270506514 0.4839418661836489 -0.4835574450959911 1.8805072630841075
        children [
          USE Wheel
        ]
        name "solid(3)"
        boundingObject USE Wheel
        physics USE Physics_wheel
        linearVelocity 1.511436439962724e-07 4.382699212563115e-08 -2.512833589604152e-06
        angularVelocity -2.0028298707638548e-07 9.173813981806413e-08 -1.3642104381335373e-08
      }
    }
    DistanceSensor {
      translation 0.13 0.06 0
      rotation 0 0 1 0.3
      children [
        DEF Sensor Shape {
          appearance PBRAppearance {
            baseColor 1 0 0
            metalness 0
          }
          geometry Box {
            size 0.05 0.035 0.025
          }
        }
      ]
      name "ds_left"
      boundingObject USE Sensor
      physics Physics {
      }
      lookupTable [
        0 0 0
        0.5 1000 0
      ]
      aperture 1.5709
    }
    DistanceSensor {
      translation 0.13 -0.06 0
      rotation 0 0 1 -0.3
      children [
        DEF Sensor Shape {
          appearance PBRAppearance {
            baseColor 1 0 0
            metalness 0
          }
          geometry Box {
            size 0.05 0.035 0.025
          }
        }
      ]
      name "ds_right"
      boundingObject USE Sensor
      physics Physics {
      }
      lookupTable [
        0 0 0
        0.5 1000 0
      ]
    }
    GPS {
      translation 0 0 0.06
      children [
        Solid {
          children [
            Shape {
              appearance PBRAppearance {
                baseColor 0 0.3 0.6
                metalness 0
              }
              geometry Cylinder {
                height 0.02
                radius 0.01
              }
            }
          ]
        }
      ]
      name "global"
    }
    InertialUnit {
      translation 0.09 3.18432e-07 0.12
      rotation 1 0 0 -5.307179586466759e-06
      children [
        Shape {
          appearance PBRAppearance {
            baseColor 1 0.9 0
            metalness 0
          }
          geometry Box {
            size 0.03 0.03 0.03
          }
        }
      ]
      name "imu"
    }
    Solid {
      translation 0 0 0.15
      children [
        Shape {
          appearance PBRAppearance {
          }
          geometry Box {
            size 0.02 0.02 0.2
          }
        }
      ]
      name "solid(4)"
    }
    SliderJoint {
      jointParameters JointParameters {
      }
      device [
        LinearMotor {
          name "linear"
          maxPosition 0.15
        }
      ]
      endPoint Solid {
        translation 0 0.075 0.21
        children [
          Shape {
            appearance PBRAppearance {
              baseColor 1 0 0
              metalness 0
            }
            geometry Box {
              size 0.025 0.15 0.025
            }
          }
        ]
        name "solid(5)"
      }
    }
    Lidar {
      translation 0.09 0 0.08
      children [
        Shape {
          appearance PBRAppearance {
          }
          geometry Cylinder {
            height 0.05
            radius 0.05
          }
        }
      ]
      horizontalResolution 256
      fieldOfView 6.2835
      numberOfLayers 1
      maxRange 6
    }
  ]
  boundingObject USE Body
  physics Physics {
  }
  controller "ros"
}
WoodenBox {
  translation -2 0 0.15
  rotation 0 1 0 0
  name "wooden box(1)"
  size 0.3 0.3 0.3
}
WoodenBox {
  translation -0.71 3.16 0.15
  rotation 0 1 0 0
  name "wooden box(2)"
  size 0.3 0.3 0.3
}
WoodenBox {
  translation 1.54 -0.65 0.15
  rotation 0 1 0 0
  name "wooden box(5)"
  size 0.5 0.4 0.3
}
WoodenBox {
  translation -2.56 -2.23 0.15
  rotation 0 1 0 0
  name "wooden box(3)"
  size 0.3 0.3 0.3
}
Wall {
  translation 0.6 -0.97 0
  rotation 0 0 1 1.5708
  name "wall(2)"
  size 0.1 2 0.3
}
Wall {
  translation -2.94 1.23 -8.49666e-08
  rotation -9.58976e-09 -9.58979e-09 1 1.5708
  name "wall(3)"
  size 0.1 2 0.3
}
Wall {
  translation -1.88 1.68 -5.60048e-08
  rotation -9.58976e-09 -9.58979e-09 1 3.14159
  name "wall(4)"
  size 0.1 1 0.3
}
Wall {
  translation -0.44 -2.45 0
  name "wall(1)"
  size 0.1 3 0.3
}
Wall {
  translation 0.76 2.47 0
  size 0.1 3 0.3
}
WoodenBox {
  translation 2.39 1.77 0.15
  rotation 0 1 0 0
  size 0.3 0.3 0.3
}
WoodenBox {
  translation 2.18 -2.59 0.15
  rotation 0 1 0 0
  name "wooden box(4)"
  size 0.3 0.3 0.3
}
